<?xml version="1.0" ?>
<robot name="bioscara" xmlns:xacro="http://www.ros.org/wiki/xacro">

<xacro:include filename="$(find bioscara_description)/urdf/materials.xacro" />
<xacro:include filename="$(find bioscara_description)/urdf/bioscara.ros2control" />
<xacro:include filename="$(find bioscara_description)/urdf/bioscara.gazebo" />
<link name="base_link">
  <inertial>
    <origin xyz="-0.04774409590466954 -1.3713643648383251e-17 0.039130407252064556" rpy="0 0 0"/>
    <mass value="41.649228123317556"/>
    <inertia ixx="0.19426" iyy="0.329216" izz="0.477531" ixy="0.0" iyz="-0.0" ixz="-0.015869"/>
  </inertial>
  <visual>
    <origin xyz="0 0 0" rpy="0 0 0"/>
    <geometry>
      <mesh filename="file://$(find bioscara_description)/meshes/base_link.stl" scale="0.001 0.001 0.001"/>
    </geometry>
    <material name="silver"/>
  </visual>
  <collision>
    <origin xyz="0 0 0" rpy="0 0 0"/>
    <geometry>
      <mesh filename="file://$(find bioscara_description)/meshes/base_link.stl" scale="0.001 0.001 0.001"/>
    </geometry>
  </collision>
</link>

<link name="link_1_1">
  <inertial>
    <origin xyz="-0.0159850493532449 0.0 0.28398899999999994" rpy="0 0 0"/>
    <mass value="200.7089851591611"/>
    <inertia ixx="5.982117" iyy="6.311802" izz="1.502498" ixy="0.0" iyz="0.0" ixz="0.0"/>
  </inertial>
  <visual>
    <origin xyz="-0.0 -0.0 -0.086" rpy="0 0 0"/>
    <geometry>
      <mesh filename="file://$(find bioscara_description)/meshes/link_1_1.stl" scale="0.001 0.001 0.001"/>
    </geometry>
    <material name="silver"/>
  </visual>
  <collision>
    <origin xyz="-0.0 -0.0 -0.086" rpy="0 0 0"/>
    <geometry>
      <mesh filename="file://$(find bioscara_description)/meshes/link_1_1.stl" scale="0.001 0.001 0.001"/>
    </geometry>
  </collision>
</link>

<link name="link_2_1">
  <inertial>
    <origin xyz="0.1639379406013823 -1.0038303710814588e-17 0.07552563377953825" rpy="0 0 0"/>
    <mass value="31.79071648534617"/>
    <inertia ixx="0.067297" iyy="0.418803" izz="0.409122" ixy="0.0" iyz="0.0" ixz="-0.039463"/>
  </inertial>
  <visual>
    <origin xyz="-0.0 -0.0 -0.172" rpy="0 0 0"/>
    <geometry>
      <mesh filename="file://$(find bioscara_description)/meshes/link_2_1.stl" scale="0.001 0.001 0.001"/>
    </geometry>
    <material name="silver"/>
  </visual>
  <collision>
    <origin xyz="-0.0 -0.0 -0.172" rpy="0 0 0"/>
    <geometry>
      <mesh filename="file://$(find bioscara_description)/meshes/link_2_1.stl" scale="0.001 0.001 0.001"/>
    </geometry>
  </collision>
</link>

<link name="link_3_1">
  <inertial>
    <origin xyz="0.14250000000000124 -2.5586863992405562e-17 -5.551115123125783e-17" rpy="0 0 0"/>
    <mass value="26.382731999662866"/>
    <inertia ixx="0.052146" iyy="0.299228" izz="0.268844" ixy="-0.0" iyz="0.0" ixz="-0.0"/>
  </inertial>
  <visual>
    <origin xyz="-0.329476 0.0 -0.25945" rpy="0 0 0"/>
    <geometry>
      <mesh filename="file://$(find bioscara_description)/meshes/link_3_1.stl" scale="0.001 0.001 0.001"/>
    </geometry>
    <material name="silver"/>
  </visual>
  <collision>
    <origin xyz="-0.329476 0.0 -0.25945" rpy="0 0 0"/>
    <geometry>
      <mesh filename="file://$(find bioscara_description)/meshes/link_3_1.stl" scale="0.001 0.001 0.001"/>
    </geometry>
  </collision>
</link>

<link name="link_4_1">
  <inertial>
    <origin xyz="2.220446049250313e-15 1.5259760060586006e-17 -0.07519999999999916" rpy="0 0 0"/>
    <mass value="1.4265673120000002"/>
    <inertia ixx="0.002783" iyy="0.002909" izz="0.000314" ixy="-0.0" iyz="-0.0" ixz="0.0"/>
  </inertial>
  <visual>
    <origin xyz="-0.614476 0.0 -0.32795" rpy="0 0 0"/>
    <geometry>
      <mesh filename="file://$(find bioscara_description)/meshes/link_4_1.stl" scale="0.001 0.001 0.001"/>
    </geometry>
    <material name="silver"/>
  </visual>
  <collision>
    <origin xyz="-0.614476 0.0 -0.32795" rpy="0 0 0"/>
    <geometry>
      <mesh filename="file://$(find bioscara_description)/meshes/link_4_1.stl" scale="0.001 0.001 0.001"/>
    </geometry>
  </collision>
</link>

<joint name="joint_1" type="revolute">
  <origin xyz="0.0 0.0 0.086" rpy="0 0 0"/>
  <parent link="base_link"/>
  <child link="link_1_1"/>
  <axis xyz="0.0 0.0 1.0"/>
  <limit upper="2.96706" lower="-2.96706" effort="100" velocity="100"/>
</joint>

<joint name="joint_2" type="prismatic">
  <origin xyz="0.0 0.0 0.086" rpy="0 0 0"/>
  <parent link="link_1_1"/>
  <child link="link_2_1"/>
  <axis xyz="0.0 0.0 1.0"/>
  <limit upper="0.25" lower="0.0" effort="100" velocity="100"/>
</joint>

<joint name="joint_3" type="revolute">
  <origin xyz="0.329476 -0.0 0.08745" rpy="0 0 0"/>
  <parent link="link_2_1"/>
  <child link="link_3_1"/>
  <axis xyz="0.0 0.0 1.0"/>
  <limit upper="2.96706" lower="-2.96706" effort="100" velocity="100"/>
</joint>

<joint name="joint_4" type="revolute">
  <origin xyz="0.285 0.0 0.0685" rpy="0 0 0"/>
  <parent link="link_3_1"/>
  <child link="link_4_1"/>
  <axis xyz="0.0 0.0 1.0"/>
  <limit upper="2.96706" lower="-2.96706" effort="100" velocity="100"/>
</joint>

</robot>
